import traceback

import pytumblr
from tenacity import retry, retry_if_result, stop_after_attempt

from utils.globals import CAT_TAGS, IMG_PATH, cfg, log


@retry(stop=stop_after_attempt(3), retry = retry_if_result(lambda result: not result))
def tumblr():
	try:
		blogname = cfg.get('tumblr.blogname')
		tumblr = pytumblr.TumblrRestClient(
			consumer_key = cfg.get('tumblr.consumer_key'),
			consumer_secret = cfg.get('tumblr.consumer_secret'),
			oauth_token = cfg.get('tumblr.oauth_token'),
			oauth_secret = cfg.get('tumblr.oauth_token_secret')
		)
	except Exception:
		log.error(f'An error occurred while authenticating to Tumblr: {traceback.format_exc()}')
		log.info('Trying again...\n')
		return

	log.info('Posting image to Tumblr')

	try:
		response = tumblr.create_photo(
			blogname = blogname,
			state = "published",
			tags = CAT_TAGS,
			data = IMG_PATH
		)

		log.success(f'Posted image to Tumblr! Link: https://{blogname}.tumblr.com/post/{response["id"]}')
		return True
	except Exception:
		log.error(f'An error while posting the image on Tumblr: {traceback.format_exc()}')
		log.info('Trying again...\n')
		return